Workbook

Sheet README
B2: KClinics Financial Model
B3: Built 2026-08-28 from the live K-Clinics catalogue + UK 2026 cost research. This workbook is the basis for refactoring pricing and cost structure for the brand — it does not touch the admin.
B5: HOW TO USE
B6: Blue text on a cream background = an input you edit. Everything else is a formula — change an input and the whole model (prices, energy, P&L) recalculates.
B7: The three levers that matter most: the utilisation ramp (Volumes, blue row), the target margins by machine class (Pricing, top), and the machinery purchase prices (Machinery — replace class-typical estimates with your invoices).
B9: TABS
B10: Assumptions — every global input with its source. • Machinery — machines, enhancements, depreciation & amortisation schedule. • Energy — seasonal A/C vs heating curve per room, base load, machine kWh, cost split. • Pricing — per-variant unit economics and recommended prices (the price architecture). • Volumes — capacity × utilisation × mix forecast. • P&L — 36 monthly columns + annual totals: gross profit, EBITDA, net profit. • Data — raw catalogue extract (audit trail).
B12: CONVENTIONS
B13: Gross profit = net revenue − variable direct costs (consumables, machine energy & service, card fees). Salaried staff are overheads. EBITDA excludes depreciation & amortisation, which are charged below it. Monthly corporation tax is a flat 19% accrual; the annual columns apply the real 2026/27 bands (19% / 26.5% marginal / 25%). AIA means cash tax in a capex year will be lower than the accrual — the accounting P&L still depreciates over asset life.
B14: VAT: the company is not VAT-registered. The P&L tracks rolling 12-month taxable turnover and switches VAT on the month after it crosses £90k (override on Assumptions). Prices are held constant at registration, so VAT comes out of margin — that is why the Pricing tab prices for the registered state by default.
B16: CATALOGUE ISSUES FOUND DURING EXTRACTION (fix in admin before publishing new prices)
B17: • Laser Skin Resurfacing: the 5-session course (£450) is cheaper than the 3-session course (£480).
... B41: Catalogue & bookings: live production DB (read-only) via authenticated admin scrape, 2026-08-28. Cost benchmarks: web research Aug 2026 — Ofgem/business tariff comparisons (energy), UK equipment vendors (machinery), UK clinic industry norms (staff, rent, marketing, insurance). Basis noted next to every assumption.

Sheet Assumptions
A1: Assumptions — every editable input in the model
A2: Blue on cream = edit me. Column D says where each number came from. Nothing else in the workbook is hardcoded.
A4: CLINIC & CAPACITY
A5: Model start month | B5: 46266 | C5: date | D5: First forecast month. Clinic re-opened 30 May 2026; model starts Sep 2026.
A6: Usable treatment rooms | B6: 9 | C6: rooms | D6: 11 active rooms in DB (3 Aesthetics, 2 Dental, 6 Treatment); 2 dental rooms excluded until dentistry launches (separate company). ESTIMATE — confirm dental rooms are not used as overflow.
A7: Rooms heated/cooled (HVAC) | B7: 9 | C7: rooms | D7: Rooms actively conditioned. Set to 11 if dental rooms are kept conditioned while mothballed.
A8: Open days per week | B8: 6 | C8: days | D8: Live booking hours imply ~57 open hours/week.
A9: Open hours per day | B9: 9.5 | C9: hours | D9: 57 open hours/week ÷ 6 days.
A10: Assumed room size | B10: 15 | C10: m² | D10: ASSUMPTION — no floor area in codebase or lease data. Drives the HVAC curve on the Energy tab.
A11: STAFFING
A12: Practitioner salary | B12: 41000 | C12: £/yr | D12: Glassdoor London aesthetic practitioner avg £41,155; skin & laser therapist UK avg £38,637, London upper half; hourly £14–£25
A13: Receptionist salary | B13: 27000 | C13: £/yr | D13: Indeed London £29,652 / PayScale £26,494; London private-clinic roles £24k–£30k
A14: Owner salary (market rate) | B14: 48000 | C14: £/yr | D14: GAP — owner remuneration undefined. £48k market-rate placeholder so owner labour is not modelled as free. Set to your actual salary/dividend policy.
A15: Employer on-cost multiplier | B15: 1.16 | C15: × | D15: 2026/27 employer NI 15% above £5,000 secondary threshold + 3% auto-enrolment pension on qualifying earnings (£6,240–£50,270) = ~15–17% on-cost for £25k–£45k staff; Employment Allowance can offset first £10,500 of NI if eligible
A16: Practitioners — headcount Y1 / Y2 / Y3 | B16: 2 | C16: 3 | D16: Y1 in column B, Y2 in column C, Y3 in column E. Defaults 2/3/5 track the default utilisation ramp. | E16: 5
A17: Receptionists — headcount Y1 / Y2 / Y3 | B17: 1 | C17: 1 | D17: Y1 in column B, Y2 in column C, Y3 in column E. | E17: 2
A18: Practitioner productive treatment hours/week | B18: 30 | C18: hrs | D18: Hours actually treating (vs admin/gaps) — drives labour cost per session in Pricing.
A19: Working weeks per year | B19: 46 | C19: wks | D19: 52 minus holiday/sickness/training.
A20: Loaded practitioner cost per treatment hour | B20: =Assumptions!$B$12*Assumptions!$B$15/(Assumptions!$B$19*Assumptions!$B$18) -> 34.463768 | C20: £/hr | D20: Calculated: salary × on-cost ÷ (working weeks × productive hours). Used in Pricing unit economics.
A21: Practitioner capacity per month | B21: =Assumptions!$B$18*Assumptions!$B$19/12 -> 115 | C21: hrs/mo | D21: Per practitioner FTE — used by the P&L capacity check.
A22: ENERGY
A23: Electricity unit rate | B23: 27 | C23: p/kWh | D23: Aug 2026 UK small-business market: AquaSwitch/BusinessEnergyDeals average ~29.6p, competitive fixed deals 20–23p; Ofgem Jul–Sep 2026 domestic cap 26.11p cross-check. 27p chosen as central figure for a micro-business on a 2026 fixed deal; small businesses pay 20% VAT on energy unless <33 kWh/day.
A24: Standing charge | B24: 55 | C24: p/day | D24: BusinessEnergyDeals/AquaSwitch Aug 2026: average 55.3p/day small business, supplier range 34.7–105.9p.
A25: Base load (lighting, fridge, autoclave, PCs) | B25: 12 | C25: kWh/day | D25: Bottom-up: LED lighting 5–8 kWh, autoclave cycles 2–4 kWh, medical/skincare fridge 1.5–3 kWh (24/7), PCs/screens/kiosk 1.5–3 kWh, misc 1–3 kWh. Consistent with Ofgem micro-business band (5,000–15,000 kWh/yr) minus HVAC.
A26: Heating & cooling | B26: see Energy tab | D26: NO GAS MODELLED — 4 Charterhouse Buildings (converted Clerkenwell building) assumed all-electric per CIBSE TM46 'general retail' zero fossil-thermal convention; heating via reverse-cycle splits at COP 3 on the electricity tariff. Confirm no gas meter on the lease (gap). Seasonal per-room kWh curve is editable on the Energy tab.
A27: PROPERTY
A28: Rent | B28: 64000 | C28: £/yr | D28: NO FLOOR AREA IN CODEBASE. Placeholder = 2,000 sqft x £32/sqft. Goswell Rd EC1M comparables Aug 2026: £27–£34/sqft (1,283 sqft at £35k pa; 972 sqft at £2,750/mo); Charterhouse Buildings is secondary frontage — use £30–£35/sqft, NOT prime Clerkenwell £50+. An 11-room clinic implies roughly 1,800–3,000 sqft; get the actual lease figure (gap).
A29: Business rates | B29: 11500 | C29: £/yr | D29: RV unknown — check VOA. 2026/27 RHL small multiplier 38.2p/£ (RV<£51k) if retail/hospitality/leisure status granted; general small multiplier 48p otherwise; RV ≤ £12k = nil via Small Business Rate Relief. Placeholder assumes RV ~£30k x 38.2p.
A30: Service charge / building costs | B30: 0 | C30: £/yr | D30: Unknown — set from the lease.
A31: OTHER OVERHEADS
A32: Insurance (treatment risk + PL + laser cover) | B32: 1500 | C32: £/yr | D32: Hamilton Fraser/PolicyBee: PI+PL from £300–£600; £1m treatment liability incl. laser/IPL from £573; device-based laser cover adds £500–£2,000. Laser-led clinic with employed staff typically £1,000–£3,000. Laser claims are ~half of insurer claims (avg payout £4,307) — do not skimp.
A33: Platform hosting & infra | B33: 50 | C33: £/mo | D33: OVERRIDES the £100/mo benchmark: K-Clinics runs its OWN booking/CRM/admin platform (this repo, Vercel + Postgres/Neon) — no third-party licence. Line = hosting/infra: Vercel Pro ~£16/mo + Neon + email/VoIP (yay.com) + AI API usage, ~£30–£100/mo. Flag: developer/maintenance time is an unmodelled cost (gap).
A34: Card processing fee | B34: 0.017 | C34: % of card takings | D34: UK SMB blended 2026: SumUp 1.69%/Square 1.75% in-person, 2.5% online/payment links. Stripe card-on-file (SetupIntent) flow in use — online-rate share will pull the blend toward 2%+; apply to ~95% of turnover (assume near-cashless).
A35: Card share of turnover | B35: 0.95 | C35: % | D35: Near-cashless assumption (Stripe card-on-file flow in use).
A36: Cleaning & sundries | B36: 400 | C36: £/mo | D36: ESTIMATE — laundry, room consumables not tied to treatments, waste disposal (clinical waste contract).
A37: Other fixed costs | B37: 200 | C37: £/mo | D37: ESTIMATE — accountancy, bank, phone/VoIP, misc subscriptions.
A38: MARKETING
A39: Marketing % of net revenue — Y1 / Y2 / Y3 | B39: 0.12 | C39: 0.1 | D39: UK aesthetic clinic benchmarks (Pulse Digital, Aesthetic Launch Lab): growing clinics 7–12%, new clinics 12–15%; single-site commit £1.5k–£5k/mo. Paid-ads CAC ~£45/booked consultation (£30–£60). Clinic reopened May 2026 — use 12–15% (or the £1,500 floor if higher) for year 1, taper to 8–10%. Y1 in B, Y2 in C, Y3 in E. | E39: 0.08
A40: Marketing monthly floor | B40: 1500 | C40: £/mo | D40: Spend floor while revenue is small — you cannot ramp without visibility. CAC benchmark ~£45/booked consultation.
A41: VAT & TAX
...

Sheet Machinery
A1: Machinery, enhancements, depreciation & amortisation
A2: Purchase prices are class-typical UK market figures (see basis column) — replace with your invoice amounts. In-service month: 0 = owned before the model starts; 1–36 = bought in that forecast month; blank = not owned (excluded). Planned hours/month is only the allocation base for service & depreciation per treatment hour in Pricing.
A4: Machine | B4: Class key | C4: Ownership | D4: Purchase £ | E4: In-service month | F4: Life (yrs) | G4: Monthly depreciation | H4: kWh per treatment hr | I4: Annual service £ | J4: Planned hours/mo | K4: Service £/hr | L4: Depreciation £/hr | M4: Consumables model | N4: Basis
A5: Diode laser hair-removal platform | B5: diode-laser | C5: OWNED (serves 63% of recent non-consultation bookings) | D5: 18000 | E5: 0 | F5: 7 | G5: =IF(E5="",0,D5/(F5*12)) -> 214.28571 | H5: 1 | I5: 1800 | J5: 250 | K5: =IF(J5=0,0,I5/12/J5) -> 0.6 | L5: =IF(J5=0,0,G5/J5) -> 0.85714286 | M5: £1–£3.50/session gel + razors (scaled by area in treatments table); handpiece stack rated 1M+ shots, replacement is a maintenance event not a per-session cost | N5: UK trade listings (thelasermachineco, britishlasers): clinic-grade £8k–£15k, premium £30k–£60k; typical premium-clinic buy £18k–£35k. Service ~10% of typical price per britishlasers contract range £1k–£3.5k. kWh: plate 2–3.5 kW at 25–40% duty (engineering estimate).
A6: Multi-application laser/IPL skin platform (shared 'laser' resource pool; may be same combi chassis as diode — Lynton Lumina class covers both for £30k–£50k) | B6: laser-ipl-platform | C6: OWNED (pigmentation/vascular/IPL/rejuvenation/resurfacing/rosacea/wrinkle/spider-vein/carbon-peel/fungal-nail all book against it) | D6: 45000 | E6: 0 | F6: 8 | G6: =IF(E6="",0,D6/(F6*12)) -> 468.75 | H6: 0.8 | I6: 3000 | J6: 30 | K6: =IF(J6=0,0,I6/12/J6) -> 8.3333333 | L6: =IF(J6=0,0,G6/J6) -> 15.625 | M6: £2/session gel; £5–£7 carbon lotion for Hollywood Peel; IPL flashlamp refurb £500–£1,500 per handpiece every ~50k–100k pulses (treat as maintenance) | N6: Lumenis Stellar M22 £45k–£70k; Lynton Lumina £28k–£50k. Service £2k–£5k/yr (Lynton/Lumenis UK contracts, 6–8% of price). Duty 25–35% of plate 1.5–3 kW.
A7: Q-switched/picosecond tattoo & pigment laser | B7: pico-laser-PLANNED | C7: NOT YET PURCHASED — phase-2 capex; tattoo/PMU pages live with prices, bookings closed | D7: 110000 | F7: 8 | G7: =IF(E7="",0,D7/(F7*12)) -> 0 | H7: 1 | I7: 7500 | J7: 25 | K7: =IF(J7=0,0,I7/12/J7) -> 25 | L7: =IF(J7=0,0,G7/J7) -> 0 | M7: ~£1–£2.50/session (gel, wipes, aftercare dressings) — negligible; service contract is the real running cost (8–10% of purchase) | N7: PicoSure Pro/PicoWay £90k–£175k; mid-tier Quanta/Lutronic £50k–£80k; Far-East pico £12.5k; Q-switched Nd:YAG alternative £15k–£40k. Model as a capex decision with three price scenarios — £110k premium figure only holds if buying PicoSure-class.
A8: Fractional CO2 laser with intimate/gynae handpiece | B8: co2-laser | C8: VERIFY — intimate line is COMING_SOON; codebase confirms the treatment tech but not that the unit is on site | D8: 55000 | E8: 0 | F8: 9 | G8: =IF(E8="",0,D8/(F8*12)) -> 509.25926 | H8: 0.4 | I8: 4000 | J8: 8 | K8: =IF(J8=0,0,I8/12/J8) -> 41.666667 | L8: =IF(J8=0,0,G8/J8) -> 63.657407 | M8: £20–£80/session single-use gynae probe covers/hygiene sleeves + numbing cream (£50 midpoint used in treatments table) | N8: Deka SmartXide/Alma FemiLift £40k–£90k with intimate handpiece; generic £5k–£15k; premium-clinic buy £45k–£65k. RF-excited tubes last 8–12 yrs. Service 6–8% of purchase.
A9: HIFU (SMAS ultrasound) with face + body cartridges | B9: hifu | C9: OWNED (live bookings) | D9: 30000 | E9: 0 | F9: 6 | G9: =IF(E9="",0,D9/(F9*12)) -> 416.66667 | H9: 0.3 | I9: 2250 | J9: 25 | K9: =IF(J9=0,0,I9/12/J9) -> 7.5 | L9: =IF(J9=0,0,G9/J9) -> 16.666667 | M9: SHOT-LIMITED CARTRIDGES — the largest device consumable line: £30–£100/session Ultraformer-class (£40 small area / £65 full face / £80 body used in treatments table); would be £300–£900/session if Ultherapy transducers. Plus gel. | N9: Classys Ultraformer III/MPT £25k–£40k UK; Ultherapy £30k–£60k; generic 7D £3k–£8k. Cartridges ~10k–20k shots at £300–£600 each. Service £1.5k–£3k/yr. Duty 30–40% of 0.5–1 kW plate.
A10: Radiofrequency skin-tightening device | B10: rf-tightening | C10: OWNED (live bookings under rf-lifting/rf-skin-tightening) | D10: 40000 | E10: 0 | F10: 7 | G10: =IF(E10="",0,D10/(F10*12)) -> 476.19048 | H10: 0.5 | I10: 3000 | J10: 12 | K10: =IF(J10=0,0,I10/12/J10) -> 20.833333 | L10: =IF(J10=0,0,G10/J10) -> 39.68254 | M10: £2–£5/session conductive gel (plain RF — catalogue has no RF-microneedling, so no Morpheus8-style £100–£180 tips) | N10: BTL Exilis Ultra £30k–£45k; mid-tier £5k–£15k; premium tier £30k–£50k. Service 5–8% of purchase. Near-continuous RF delivery, duty 40–60%.
A11: HydraFacial-style vortex facial platform | B11: hydrafacial-platform | C11: OWNED (live bookings) | D11: 25000 | E11: 0 | F11: 6 | G11: =IF(E11="",0,D11/(F11*12)) -> 347.22222 | H11: 0.2 | I11: 1500 | J11: 60 | K11: =IF(J11=0,0,I11/12/J11) -> 2.0833333 | L11: =IF(J11=0,0,G11/J11) -> 5.787037 | M11: £15–£25/session tips + branded serums, scaling with tier (Signature £15 / Deluxe £20 / Platinum £25); genuine HydraFacial ties serum purchase to warranty. Deep Cleansing menu on same platform at £8–£15/session products. | N11: Genuine HydraFacial Syndeo/Elite £20k–£32k UK; clones £3k–£8k. Consumables $20–$30/treatment (konmison/workee).
A12: Endosphere compressive micro-vibration + anti-cellulite vacuum body platform | B12: endosphere-vacuum | C12: OWNED (body-contouring + vacuum-massage bookings) | D12: 27000 | E12: 0 | F12: 7 | G12: =IF(E12="",0,D12/(F12*12)) -> 321.42857 | H12: 0.35 | I12: 1750 | J12: 45 | K12: =IF(J12=0,0,I12/12/J12) -> 3.2407407 | L12: =IF(J12=0,0,G12/J12) -> 7.1428571 | M12: £1–£3/session oil/cream/disposable bodysuits | N12: Endospheres AK Body dealer pricing ~€25k–€35k (~£21k–£30k, baltic-lasers.eu) — DEALER-QUOTE ESTIMATE, not published list price. Service/roller refurb ~5% of price. Motor runs near-continuously at 0.3–0.5 kW.
A13: Microneedling pen (+ BB Glow micro-channelling) | B13: microneedling-pen | C13: OWNED (live bookings) | D13: 3000 | E13: 0 | F13: 4 | G13: =IF(E13="",0,D13/(F13*12)) -> 62.5 | H13: 0.02 | I13: 100 | J13: 18 | K13: =IF(J13=0,0,I13/12/J13) -> 0.46296296 | L13: =IF(J13=0,0,G13/J13) -> 3.4722222 | M13: £5–£35/session sterile needle cartridge + serum (SkinPen cartridges £25–£35, generic £5–£20); BB Glow tinted ampoule £5–£15 extra | N13: SkinPen Precision £2k–£3.5k, Dermapen 4 £3k–£5.5k. Negligible power. Battery/handpiece wear limits life to 3–5 yrs.
A14: Microdermabrasion device (diamond-tip/crystal) | B14: microdermabrasion | C14: OWNED (1 booking in 90d) | D14: 3000 | E14: 0 | F14: 6 | G14: =IF(E14="",0,D14/(F14*12)) -> 41.666667 | H14: 0.25 | I14: 300 | J14: 8 | K14: =IF(J14=0,0,I14/12/J14) -> 3.125 | L14: =IF(J14=0,0,G14/J14) -> 5.2083333 | M14: £1–£3/session filters + disposable tips (crystals £3–£5 if crystal type) | N14: UK professional diamond-tip units £1.2k–£6k, typical £2.5k–£3.5k. Vacuum pump 0.2–0.4 kW near-continuous.
A15: Microcurrent facial toning device + LED panel | B15: microcurrent-led | C15: AMBIGUOUS — codebase marks microcurrent/LED 'onRequest, machine not yet in', but the live catalogue lists Microcurrent lifting and LED as NORMAL and there are 6 microcurrent-facial bookings in 90d. Assume a non-CACI-branded unit is on site; confirm with owner. | D15: 15000 | E15: 0 | F15: 8 | G15: =IF(E15="",0,D15/(F15*12)) -> 156.25 | H15: 0.1 | I15: 750 | J15: 25 | K15: =IF(J15=0,0,I15/12/J15) -> 2.5 | L15: =IF(J15=0,0,G15/J15) -> 6.25 | M15: £2–£5/session conductive gel, cotton buds; hydra mask +£5; LED session ~£1 | N15: CACI Synergy £14k–£17k inc training, Ultimate £18k–£22k, Classic £9k–£12k (dealer channel, prices on application). If the on-site unit is a generic microcurrent+LED device the capex could be £2k–£5k — use the low end unless CACI-branded purchase is confirmed.
A16: Injectables room (no machine): electric couch + MHRA-compliant medical fridge + sharps/emergency kit | B16: none-injectables | C16: OWNED | D16: 2500 | E16: 0 | F16: 10 | G16: =IF(E16="",0,D16/(F16*12)) -> 20.833333 | H16: 0 | I16: 150 | J16: 25 | K16: =IF(J16=0,0,I16/12/J16) -> 0.5 | L16: =IF(J16=0,0,G16/J16) -> 0.83333333 | M16: DOMINANT COGS LINE: toxin vials £45–£85/tx by area count, HA filler £35–£85/tx by ml, fat-dissolving vials £35–£75/tx, polynucleotides £70–£100/tx, meso cocktails £25/tx, plus needles/cannulae/numbing (in per-row figures). Fridge runs 24/7: ~1.5–3 kWh/day counted in base load, not per-treatment. | N16: Couch £700–£2,500, pharmacy fridge £400–£1,500, kit £200–£500. Injectable COGS from UK aesthetic wholesale norms (Church Pharmacy tier) — brand-dependent estimates, no recorded costs.
A17: Topical/manual treatment room kit (couch, trolley, steamer, hot cabinet) | B17: none-manual | C17: OWNED | D17: 1500 | E17: 0 | F17: 9 | G17: =IF(E17="",0,D17/(F17*12)) -> 13.888889 | H17: 0.1 | I17: 100 | J17: 25 | K17: =IF(J17=0,0,I17/12/J17) -> 0.33333333 | L17: =IF(J17=0,0,G17/J17) -> 0.55555556 | M17: £1.50–£15/session: peel solutions + neutralisers £10–£15, massage oils £2–£4, masks/towels/products £3–£8 | N17: UK salon equipment norms; steamer ~0.3 kW only while on.
A20: ENHANCEMENTS & FIT-OUT (amortised)
A21: Item | C21: Notes | D21: Cost £ | E21: In-service month | F21: Life (yrs) | G21: Monthly amortisation
A22: Initial fit-out / leasehold improvements | C22: GAP — fit-out spend on 4 Charterhouse Buildings unknown. Enter the capitalised amount; it amortises over the life you set. | D22: 0 | E22: 0 | F22: 10 | G22: =IF(OR(E22="",F22=0),0,D22/(F22*12)) -> 0
A23: EXAMPLE — reception refresh (edit or zero out) | C23: Example row showing the expected format. | D23: 8000 | E23: 6 | F23: 5 | G23: =IF(OR(E23="",F23=0),0,D23/(F23*12)) -> 133.33333
A24: Planned enhancement 2 | D24: 0 | F24: 5 | G24: =IF(OR(E24="",F24=0),0,D24/(F24*12)) -> 0
A25: Planned enhancement 3 | D25: 0 | F25: 5 | G25: =IF(OR(E25="",F25=0),0,D25/(F25*12)) -> 0
A26: Planned enhancement 4 | D26: 0 | F26: 5 | G26: =IF(OR(E26="",F26=0),0,D26/(F26*12)) -> 0
A29: MONTHLY D&A SCHEDULE (feeds P&L)
A30: Month # | B30: 1 | C30: 2 | D30: 3 | E30: 4 | F30: 5 | G30: 6 | H30: 7 | I30: 8 | J30: 9 | K30: 10 | L30: 11 | M30: 12 | N30: 13 | O30: 14 | P30: 15 | Q30: 16 | R30: 17 | S30: 18 | T30: 19 | U30: 20 | V30: 21 | W30: 22 | X30: 23 | Y30: 24 | Z30: 25 | AA30: 26 | AB30: 27 | AC30: 28 | AD30: 29 | AE30: 30 | AF30: 31 | AG30: 32 | AH30: 33 | AI30: 34 | AJ30: 35 | AK30: 36
A31: =A5 -> Diode laser hair-removal platform | B31: =IF($E5="",0,IF(AND(COLUMN()-1>=MAX($E5,1),COLUMN()-1<$E5+$F5*12),$G5,0)) -> 214.28571 | C31: =IF($E5="",0,IF(AND(COLUMN()-1>=MAX($E5,1),COLUMN()-1<$E5+$F5*12),$G5,0)) -> 214.28571 | D31: =IF($E5="",0,IF(AND(COLUMN()-1>=MAX($E5,1),COLUMN()-1<$E5+$F5*12),$G5,0)) -> 214.28571 | E31: =IF($E5="",0,IF(AND(COLUMN()-1>=MAX($E5,1),COLUMN()-1<$E5+$F5*12),$G5,0)) -> 214.28571 | F31: =IF($E5="",0,IF(AND(COLUMN()-1>=MAX($E5,1),COLUMN()-1<$E5+$F5*12),$G5,0)) -> 214.28571 | G31: =IF($E5="",0,IF(AND(COLUMN()-1>=MAX($E5,1),COLUMN()-1<$E5+$F5*12),$G5,0)) -> 214.28571 | H31: =IF($E5="",0,IF(AND(COLUMN()-1>=MAX($E5,1),COLUMN()-1<$E5+$F5*12),$G5,0)) -> 214.28571 | I31: =IF($E5="",0,IF(AND(COLUMN()-1>=MAX($E5,1),COLUMN()-1<$E5+$F5*12),$G5,0)) -> 214.28571 | ... AK31: =IF($E5="",0,IF(AND(COLUMN()-1>=MAX($E5,1),COLUMN()-1<$E5+$F5*12),$G5,0)) -> 214.28571
A32: =A6 -> Multi-application laser/IPL skin platform (shared 'laser' resource pool; may be same combi chassis as diode — Lynton Lumina class covers both for £30k–£50k) | B32: =IF($E6="",0,IF(AND(COLUMN()-1>=MAX($E6,1),COLUMN()-1<$E6+$F6*12),$G6,0)) -> 468.75 | C32: =IF($E6="",0,IF(AND(COLUMN()-1>=MAX($E6,1),COLUMN()-1<$E6+$F6*12),$G6,0)) -> 468.75 | D32: =IF($E6="",0,IF(AND(COLUMN()-1>=MAX($E6,1),COLUMN()-1<$E6+$F6*12),$G6,0)) -> 468.75 | E32: =IF($E6="",0,IF(AND(COLUMN()-1>=MAX($E6,1),COLUMN()-1<$E6+$F6*12),$G6,0)) -> 468.75 | F32: =IF($E6="",0,IF(AND(COLUMN()-1>=MAX($E6,1),COLUMN()-1<$E6+$F6*12),$G6,0)) -> 468.75 | G32: =IF($E6="",0,IF(AND(COLUMN()-1>=MAX($E6,1),COLUMN()-1<$E6+$F6*12),$G6,0)) -> 468.75 | H32: =IF($E6="",0,IF(AND(COLUMN()-1>=MAX($E6,1),COLUMN()-1<$E6+$F6*12),$G6,0)) -> 468.75 | I32: =IF($E6="",0,IF(AND(COLUMN()-1>=MAX($E6,1),COLUMN()-1<$E6+$F6*12),$G6,0)) -> 468.75 | ... AK32: =IF($E6="",0,IF(AND(COLUMN()-1>=MAX($E6,1),COLUMN()-1<$E6+$F6*12),$G6,0)) -> 468.75
A33: =A7 -> Q-switched/picosecond tattoo & pigment laser | B33: =IF($E7="",0,IF(AND(COLUMN()-1>=MAX($E7,1),COLUMN()-1<$E7+$F7*12),$G7,0)) -> 0 | C33: =IF($E7="",0,IF(AND(COLUMN()-1>=MAX($E7,1),COLUMN()-1<$E7+$F7*12),$G7,0)) -> 0 | D33: =IF($E7="",0,IF(AND(COLUMN()-1>=MAX($E7,1),COLUMN()-1<$E7+$F7*12),$G7,0)) -> 0 | E33: =IF($E7="",0,IF(AND(COLUMN()-1>=MAX($E7,1),COLUMN()-1<$E7+$F7*12),$G7,0)) -> 0 | F33: =IF($E7="",0,IF(AND(COLUMN()-1>=MAX($E7,1),COLUMN()-1<$E7+$F7*12),$G7,0)) -> 0 | G33: =IF($E7="",0,IF(AND(COLUMN()-1>=MAX($E7,1),COLUMN()-1<$E7+$F7*12),$G7,0)) -> 0 | H33: =IF($E7="",0,IF(AND(COLUMN()-1>=MAX($E7,1),COLUMN()-1<$E7+$F7*12),$G7,0)) -> 0 | I33: =IF($E7="",0,IF(AND(COLUMN()-1>=MAX($E7,1),COLUMN()-1<$E7+$F7*12),$G7,0)) -> 0 | ... AK33: =IF($E7="",0,IF(AND(COLUMN()-1>=MAX($E7,1),COLUMN()-1<$E7+$F7*12),$G7,0)) -> 0
A34: =A8 -> Fractional CO2 laser with intimate/gynae handpiece | B34: =IF($E8="",0,IF(AND(COLUMN()-1>=MAX($E8,1),COLUMN()-1<$E8+$F8*12),$G8,0)) -> 509.25926 | C34: =IF($E8="",0,IF(AND(COLUMN()-1>=MAX($E8,1),COLUMN()-1<$E8+$F8*12),$G8,0)) -> 509.25926 | D34: =IF($E8="",0,IF(AND(COLUMN()-1>=MAX($E8,1),COLUMN()-1<$E8+$F8*12),$G8,0)) -> 509.25926 | E34: =IF($E8="",0,IF(AND(COLUMN()-1>=MAX($E8,1),COLUMN()-1<$E8+$F8*12),$G8,0)) -> 509.25926 | F34: =IF($E8="",0,IF(AND(COLUMN()-1>=MAX($E8,1),COLUMN()-1<$E8+$F8*12),$G8,0)) -> 509.25926 | G34: =IF($E8="",0,IF(AND(COLUMN()-1>=MAX($E8,1),COLUMN()-1<$E8+$F8*12),$G8,0)) -> 509.25926 | H34: =IF($E8="",0,IF(AND(COLUMN()-1>=MAX($E8,1),COLUMN()-1<$E8+$F8*12),$G8,0)) -> 509.25926 | I34: =IF($E8="",0,IF(AND(COLUMN()-1>=MAX($E8,1),COLUMN()-1<$E8+$F8*12),$G8,0)) -> 509.25926 | ... AK34: =IF($E8="",0,IF(AND(COLUMN()-1>=MAX($E8,1),COLUMN()-1<$E8+$F8*12),$G8,0)) -> 509.25926
A35: =A9 -> HIFU (SMAS ultrasound) with face + body cartridges | B35: =IF($E9="",0,IF(AND(COLUMN()-1>=MAX($E9,1),COLUMN()-1<$E9+$F9*12),$G9,0)) -> 416.66667 | C35: =IF($E9="",0,IF(AND(COLUMN()-1>=MAX($E9,1),COLUMN()-1<$E9+$F9*12),$G9,0)) -> 416.66667 | D35: =IF($E9="",0,IF(AND(COLUMN()-1>=MAX($E9,1),COLUMN()-1<$E9+$F9*12),$G9,0)) -> 416.66667 | E35: =IF($E9="",0,IF(AND(COLUMN()-1>=MAX($E9,1),COLUMN()-1<$E9+$F9*12),$G9,0)) -> 416.66667 | F35: =IF($E9="",0,IF(AND(COLUMN()-1>=MAX($E9,1),COLUMN()-1<$E9+$F9*12),$G9,0)) -> 416.66667 | G35: =IF($E9="",0,IF(AND(COLUMN()-1>=MAX($E9,1),COLUMN()-1<$E9+$F9*12),$G9,0)) -> 416.66667 | H35: =IF($E9="",0,IF(AND(COLUMN()-1>=MAX($E9,1),COLUMN()-1<$E9+$F9*12),$G9,0)) -> 416.66667 | I35: =IF($E9="",0,IF(AND(COLUMN()-1>=MAX($E9,1),COLUMN()-1<$E9+$F9*12),$G9,0)) -> 416.66667 | ... AK35: =IF($E9="",0,IF(AND(COLUMN()-1>=MAX($E9,1),COLUMN()-1<$E9+$F9*12),$G9,0)) -> 416.66667
A36: =A10 -> Radiofrequency skin-tightening device | B36: =IF($E10="",0,IF(AND(COLUMN()-1>=MAX($E10,1),COLUMN()-1<$E10+$F10*12),$G10,0)) -> 476.19048 | C36: =IF($E10="",0,IF(AND(COLUMN()-1>=MAX($E10,1),COLUMN()-1<$E10+$F10*12),$G10,0)) -> 476.19048 | D36: =IF($E10="",0,IF(AND(COLUMN()-1>=MAX($E10,1),COLUMN()-1<$E10+$F10*12),$G10,0)) -> 476.19048 | E36: =IF($E10="",0,IF(AND(COLUMN()-1>=MAX($E10,1),COLUMN()-1<$E10+$F10*12),$G10,0)) -> 476.19048 | F36: =IF($E10="",0,IF(AND(COLUMN()-1>=MAX($E10,1),COLUMN()-1<$E10+$F10*12),$G10,0)) -> 476.19048 | G36: =IF($E10="",0,IF(AND(COLUMN()-1>=MAX($E10,1),COLUMN()-1<$E10+$F10*12),$G10,0)) -> 476.19048 | H36: =IF($E10="",0,IF(AND(COLUMN()-1>=MAX($E10,1),COLUMN()-1<$E10+$F10*12),$G10,0)) -> 476.19048 | I36: =IF($E10="",0,IF(AND(COLUMN()-1>=MAX($E10,1),COLUMN()-1<$E10+$F10*12),$G10,0)) -> 476.19048 | ... AK36: =IF($E10="",0,IF(AND(COLUMN()-1>=MAX($E10,1),COLUMN()-1<$E10+$F10*12),$G10,0)) -> 476.19048
A37: =A11 -> HydraFacial-style vortex facial platform | B37: =IF($E11="",0,IF(AND(COLUMN()-1>=MAX($E11,1),COLUMN()-1<$E11+$F11*12),$G11,0)) -> 347.22222 | C37: =IF($E11="",0,IF(AND(COLUMN()-1>=MAX($E11,1),COLUMN()-1<$E11+$F11*12),$G11,0)) -> 347.22222 | D37: =IF($E11="",0,IF(AND(COLUMN()-1>=MAX($E11,1),COLUMN()-1<$E11+$F11*12),$G11,0)) -> 347.22222 | E37: =IF($E11="",0,IF(AND(COLUMN()-1>=MAX($E11,1),COLUMN()-1<$E11+$F11*12),$G11,0)) -> 347.22222 | F37: =IF($E11="",0,IF(AND(COLUMN()-1>=MAX($E11,1),COLUMN()-1<$E11+$F11*12),$G11,0)) -> 347.22222 | G37: =IF($E11="",0,IF(AND(COLUMN()-1>=MAX($E11,1),COLUMN()-1<$E11+$F11*12),$G11,0)) -> 347.22222 | H37: =IF($E11="",0,IF(AND(COLUMN()-1>=MAX($E11,1),COLUMN()-1<$E11+$F11*12),$G11,0)) -> 347.22222 | I37: =IF($E11="",0,IF(AND(COLUMN()-1>=MAX($E11,1),COLUMN()-1<$E11+$F11*12),$G11,0)) -> 347.22222 | ... AK37: =IF($E11="",0,IF(AND(COLUMN()-1>=MAX($E11,1),COLUMN()-1<$E11+$F11*12),$G11,0)) -> 347.22222
A38: =A12 -> Endosphere compressive micro-vibration + anti-cellulite vacuum body platform | B38: =IF($E12="",0,IF(AND(COLUMN()-1>=MAX($E12,1),COLUMN()-1<$E12+$F12*12),$G12,0)) -> 321.42857 | C38: =IF($E12="",0,IF(AND(COLUMN()-1>=MAX($E12,1),COLUMN()-1<$E12+$F12*12),$G12,0)) -> 321.42857 | D38: =IF($E12="",0,IF(AND(COLUMN()-1>=MAX($E12,1),COLUMN()-1<$E12+$F12*12),$G12,0)) -> 321.42857 | E38: =IF($E12="",0,IF(AND(COLUMN()-1>=MAX($E12,1),COLUMN()-1<$E12+$F12*12),$G12,0)) -> 321.42857 | F38: =IF($E12="",0,IF(AND(COLUMN()-1>=MAX($E12,1),COLUMN()-1<$E12+$F12*12),$G12,0)) -> 321.42857 | G38: =IF($E12="",0,IF(AND(COLUMN()-1>=MAX($E12,1),COLUMN()-1<$E12+$F12*12),$G12,0)) -> 321.42857 | H38: =IF($E12="",0,IF(AND(COLUMN()-1>=MAX($E12,1),COLUMN()-1<$E12+$F12*12),$G12,0)) -> 321.42857 | I38: =IF($E12="",0,IF(AND(COLUMN()-1>=MAX($E12,1),COLUMN()-1<$E12+$F12*12),$G12,0)) -> 321.42857 | ... AK38: =IF($E12="",0,IF(AND(COLUMN()-1>=MAX($E12,1),COLUMN()-1<$E12+$F12*12),$G12,0)) -> 321.42857
A39: =A13 -> Microneedling pen (+ BB Glow micro-channelling) | B39: =IF($E13="",0,IF(AND(COLUMN()-1>=MAX($E13,1),COLUMN()-1<$E13+$F13*12),$G13,0)) -> 62.5 | C39: =IF($E13="",0,IF(AND(COLUMN()-1>=MAX($E13,1),COLUMN()-1<$E13+$F13*12),$G13,0)) -> 62.5 | D39: =IF($E13="",0,IF(AND(COLUMN()-1>=MAX($E13,1),COLUMN()-1<$E13+$F13*12),$G13,0)) -> 62.5 | E39: =IF($E13="",0,IF(AND(COLUMN()-1>=MAX($E13,1),COLUMN()-1<$E13+$F13*12),$G13,0)) -> 62.5 | F39: =IF($E13="",0,IF(AND(COLUMN()-1>=MAX($E13,1),COLUMN()-1<$E13+$F13*12),$G13,0)) -> 62.5 | G39: =IF($E13="",0,IF(AND(COLUMN()-1>=MAX($E13,1),COLUMN()-1<$E13+$F13*12),$G13,0)) -> 62.5 | H39: =IF($E13="",0,IF(AND(COLUMN()-1>=MAX($E13,1),COLUMN()-1<$E13+$F13*12),$G13,0)) -> 62.5 | I39: =IF($E13="",0,IF(AND(COLUMN()-1>=MAX($E13,1),COLUMN()-1<$E13+$F13*12),$G13,0)) -> 62.5 | ... AK39: =IF($E13="",0,IF(AND(COLUMN()-1>=MAX($E13,1),COLUMN()-1<$E13+$F13*12),$G13,0)) -> 62.5
A40: =A14 -> Microdermabrasion device (diamond-tip/crystal) | B40: =IF($E14="",0,IF(AND(COLUMN()-1>=MAX($E14,1),COLUMN()-1<$E14+$F14*12),$G14,0)) -> 41.666667 | C40: =IF($E14="",0,IF(AND(COLUMN()-1>=MAX($E14,1),COLUMN()-1<$E14+$F14*12),$G14,0)) -> 41.666667 | D40: =IF($E14="",0,IF(AND(COLUMN()-1>=MAX($E14,1),COLUMN()-1<$E14+$F14*12),$G14,0)) -> 41.666667 | E40: =IF($E14="",0,IF(AND(COLUMN()-1>=MAX($E14,1),COLUMN()-1<$E14+$F14*12),$G14,0)) -> 41.666667 | F40: =IF($E14="",0,IF(AND(COLUMN()-1>=MAX($E14,1),COLUMN()-1<$E14+$F14*12),$G14,0)) -> 41.666667 | G40: =IF($E14="",0,IF(AND(COLUMN()-1>=MAX($E14,1),COLUMN()-1<$E14+$F14*12),$G14,0)) -> 41.666667 | H40: =IF($E14="",0,IF(AND(COLUMN()-1>=MAX($E14,1),COLUMN()-1<$E14+$F14*12),$G14,0)) -> 41.666667 | I40: =IF($E14="",0,IF(AND(COLUMN()-1>=MAX($E14,1),COLUMN()-1<$E14+$F14*12),$G14,0)) -> 41.666667 | ... AK40: =IF($E14="",0,IF(AND(COLUMN()-1>=MAX($E14,1),COLUMN()-1<$E14+$F14*12),$G14,0)) -> 41.666667
A41: =A15 -> Microcurrent facial toning device + LED panel | B41: =IF($E15="",0,IF(AND(COLUMN()-1>=MAX($E15,1),COLUMN()-1<$E15+$F15*12),$G15,0)) -> 156.25 | C41: =IF($E15="",0,IF(AND(COLUMN()-1>=MAX($E15,1),COLUMN()-1<$E15+$F15*12),$G15,0)) -> 156.25 | D41: =IF($E15="",0,IF(AND(COLUMN()-1>=MAX($E15,1),COLUMN()-1<$E15+$F15*12),$G15,0)) -> 156.25 | E41: =IF($E15="",0,IF(AND(COLUMN()-1>=MAX($E15,1),COLUMN()-1<$E15+$F15*12),$G15,0)) -> 156.25 | F41: =IF($E15="",0,IF(AND(COLUMN()-1>=MAX($E15,1),COLUMN()-1<$E15+$F15*12),$G15,0)) -> 156.25 | G41: =IF($E15="",0,IF(AND(COLUMN()-1>=MAX($E15,1),COLUMN()-1<$E15+$F15*12),$G15,0)) -> 156.25 | H41: =IF($E15="",0,IF(AND(COLUMN()-1>=MAX($E15,1),COLUMN()-1<$E15+$F15*12),$G15,0)) -> 156.25 | I41: =IF($E15="",0,IF(AND(COLUMN()-1>=MAX($E15,1),COLUMN()-1<$E15+$F15*12),$G15,0)) -> 156.25 | ... AK41: =IF($E15="",0,IF(AND(COLUMN()-1>=MAX($E15,1),COLUMN()-1<$E15+$F15*12),$G15,0)) -> 156.25
A42: =A16 -> Injectables room (no machine): electric couch + MHRA-compliant medical fridge + sharps/emergency kit | B42: =IF($E16="",0,IF(AND(COLUMN()-1>=MAX($E16,1),COLUMN()-1<$E16+$F16*12),$G16,0)) -> 20.833333 | C42: =IF($E16="",0,IF(AND(COLUMN()-1>=MAX($E16,1),COLUMN()-1<$E16+$F16*12),$G16,0)) -> 20.833333 | D42: =IF($E16="",0,IF(AND(COLUMN()-1>=MAX($E16,1),COLUMN()-1<$E16+$F16*12),$G16,0)) -> 20.833333 | E42: =IF($E16="",0,IF(AND(COLUMN()-1>=MAX($E16,1),COLUMN()-1<$E16+$F16*12),$G16,0)) -> 20.833333 | F42: =IF($E16="",0,IF(AND(COLUMN()-1>=MAX($E16,1),COLUMN()-1<$E16+$F16*12),$G16,0)) -> 20.833333 | G42: =IF($E16="",0,IF(AND(COLUMN()-1>=MAX($E16,1),COLUMN()-1<$E16+$F16*12),$G16,0)) -> 20.833333 | H42: =IF($E16="",0,IF(AND(COLUMN()-1>=MAX($E16,1),COLUMN()-1<$E16+$F16*12),$G16,0)) -> 20.833333 | I42: =IF($E16="",0,IF(AND(COLUMN()-1>=MAX($E16,1),COLUMN()-1<$E16+$F16*12),$G16,0)) -> 20.833333 | ... AK42: =IF($E16="",0,IF(AND(COLUMN()-1>=MAX($E16,1),COLUMN()-1<$E16+$F16*12),$G16,0)) -> 20.833333
A43: =A17 -> Topical/manual treatment room kit (couch, trolley, steamer, hot cabinet) | B43: =IF($E17="",0,IF(AND(COLUMN()-1>=MAX($E17,1),COLUMN()-1<$E17+$F17*12),$G17,0)) -> 13.888889 | C43: =IF($E17="",0,IF(AND(COLUMN()-1>=MAX($E17,1),COLUMN()-1<$E17+$F17*12),$G17,0)) -> 13.888889 | D43: =IF($E17="",0,IF(AND(COLUMN()-1>=MAX($E17,1),COLUMN()-1<$E17+$F17*12),$G17,0)) -> 13.888889 | E43: =IF($E17="",0,IF(AND(COLUMN()-1>=MAX($E17,1),COLUMN()-1<$E17+$F17*12),$G17,0)) -> 13.888889 | F43: =IF($E17="",0,IF(AND(COLUMN()-1>=MAX($E17,1),COLUMN()-1<$E17+$F17*12),$G17,0)) -> 13.888889 | G43: =IF($E17="",0,IF(AND(COLUMN()-1>=MAX($E17,1),COLUMN()-1<$E17+$F17*12),$G17,0)) -> 13.888889 | H43: =IF($E17="",0,IF(AND(COLUMN()-1>=MAX($E17,1),COLUMN()-1<$E17+$F17*12),$G17,0)) -> 13.888889 | I43: =IF($E17="",0,IF(AND(COLUMN()-1>=MAX($E17,1),COLUMN()-1<$E17+$F17*12),$G17,0)) -> 13.888889 | ... AK43: =IF($E17="",0,IF(AND(COLUMN()-1>=MAX($E17,1),COLUMN()-1<$E17+$F17*12),$G17,0)) -> 13.888889
A44: =A22 -> Initial fit-out / leasehold improvements | B44: =IF(OR($E22="",$F22=0),0,IF(AND(COLUMN()-1>=MAX($E22,1),COLUMN()-1<$E22+$F22*12),$G22,0)) -> 0 | C44: =IF(OR($E22="",$F22=0),0,IF(AND(COLUMN()-1>=MAX($E22,1),COLUMN()-1<$E22+$F22*12),$G22,0)) -> 0 | D44: =IF(OR($E22="",$F22=0),0,IF(AND(COLUMN()-1>=MAX($E22,1),COLUMN()-1<$E22+$F22*12),$G22,0)) -> 0 | E44: =IF(OR($E22="",$F22=0),0,IF(AND(COLUMN()-1>=MAX($E22,1),COLUMN()-1<$E22+$F22*12),$G22,0)) -> 0 | F44: =IF(OR($E22="",$F22=0),0,IF(AND(COLUMN()-1>=MAX($E22,1),COLUMN()-1<$E22+$F22*12),$G22,0)) -> 0 | G44: =IF(OR($E22="",$F22=0),0,IF(AND(COLUMN()-1>=MAX($E22,1),COLUMN()-1<$E22+$F22*12),$G22,0)) -> 0 | H44: =IF(OR($E22="",$F22=0),0,IF(AND(COLUMN()-1>=MAX($E22,1),COLUMN()-1<$E22+$F22*12),$G22,0)) -> 0 | I44: =IF(OR($E22="",$F22=0),0,IF(AND(COLUMN()-1>=MAX($E22,1),COLUMN()-1<$E22+$F22*12),$G22,0)) -> 0 | ... AK44: =IF(OR($E22="",$F22=0),0,IF(AND(COLUMN()-1>=MAX($E22,1),COLUMN()-1<$E22+$F22*12),$G22,0)) -> 0
A45: =A23 -> EXAMPLE — reception refresh (edit or zero out) | B45: =IF(OR($E23="",$F23=0),0,IF(AND(COLUMN()-1>=MAX($E23,1),COLUMN()-1<$E23+$F23*12),$G23,0)) -> 0 | C45: =IF(OR($E23="",$F23=0),0,IF(AND(COLUMN()-1>=MAX($E23,1),COLUMN()-1<$E23+$F23*12),$G23,0)) -> 0 | D45: =IF(OR($E23="",$F23=0),0,IF(AND(COLUMN()-1>=MAX($E23,1),COLUMN()-1<$E23+$F23*12),$G23,0)) -> 0 | E45: =IF(OR($E23="",$F23=0),0,IF(AND(COLUMN()-1>=MAX($E23,1),COLUMN()-1<$E23+$F23*12),$G23,0)) -> 0 | F45: =IF(OR($E23="",$F23=0),0,IF(AND(COLUMN()-1>=MAX($E23,1),COLUMN()-1<$E23+$F23*12),$G23,0)) -> 0 | G45: =IF(OR($E23="",$F23=0),0,IF(AND(COLUMN()-1>=MAX($E23,1),COLUMN()-1<$E23+$F23*12),$G23,0)) -> 133.33333 | H45: =IF(OR($E23="",$F23=0),0,IF(AND(COLUMN()-1>=MAX($E23,1),COLUMN()-1<$E23+$F23*12),$G23,0)) -> 133.33333 | I45: =IF(OR($E23="",$F23=0),0,IF(AND(COLUMN()-1>=MAX($E23,1),COLUMN()-1<$E23+$F23*12),$G23,0)) -> 133.33333 | ... AK45: =IF(OR($E23="",$F23=0),0,IF(AND(COLUMN()-1>=MAX($E23,1),COLUMN()-1<$E23+$F23*12),$G23,0)) -> 133.33333
...

Sheet Pricing
A1: Treatment pricing architecture — unit economics per variant
A2: Every recommended price is a formula: fully-loaded cost ÷ (1 − target margin − card-fee drag), then VAT, then rounding. Change the levers below or any machine/labour assumption and the whole price list moves. Current prices scraped from the live admin catalogue on 2026-08-28. Recorded COGS is empty on every variant, so consumables are researched estimates (blue).
A4: LEVERS
A5: Price for the VAT-registered state? (1 = yes) | B5: 1 | C5: 1 = recommended prices keep their margin AFTER VAT registration (the safe basis for a durable price list). 0 = price for today's unregistered state.
A6: Round recommended prices to nearest £ | B6: 1 | C6: 1, 5 or 9 — e.g. 5 gives £85/£90-style pricing.
A7: Course discount — 3 sessions | B7: 0.1 | C7: Per-session discount vs single price. Current live courses average ~15% off.
A8: Course discount — 6 sessions | B8: 0.15
A9: Course discount — 10 sessions | B9: 0.2
A11: TARGET CONTRIBUTION MARGIN BY MACHINE CLASS
A12: Class | B12: Target margin | C12: Margin = (net revenue − fully-loaded cost) ÷ net revenue. Fully-loaded cost includes consumables, machine energy, machine service & depreciation per hour, practitioner time and card fees.
A13: diode-laser | B13: 0.7
A14: laser-ipl-platform | B14: 0.7
A15: pico-laser-PLANNED | B15: 0.7
A16: co2-laser | B16: 0.7
A17: hifu | B17: 0.6
A18: rf-tightening | B18: 0.7
A19: hydrafacial-platform | B19: 0.65
A20: endosphere-vacuum | B20: 0.7
A21: microneedling-pen | B21: 0.65
A22: microdermabrasion | B22: 0.7
A23: microcurrent-led | B23: 0.7
A24: none-injectables | B24: 0.55
A25: none-manual | B25: 0.65
A28: Service | B28: Variant | C28: Category | D28: Status | E28: Machine class | F28: Internal min | G28: Machine min | H28: VAT % | I28: Current price £ | J28: Current net £ | K28: Consumables £ | L28: Machine energy £ | M28: Machine service £ | N28: Machine depreciation £ | O28: Practitioner £ | P28: Card fee £ | Q28: Fully-loaded cost £ | R28: Contribution £ | S28: Contribution % | T28: Target % | U28: Recommended net £ | V28: Recommended price £ | W28: Δ vs current | X28: Course 3 rec £ | Y28: Course 6 rec £ | Z28: Course 10 rec £ | AA28: Current course 6 £ | AB28: Current 6-course discount | AC28: Sellable
A29: Laser Hair Removal — Women | B29: Bikini Line | C29: aesthetics | D29: CONSULTATION | E29: diode-laser | F29: 20 | G29: 20 | H29: 0.2 | I29: 35 | J29: =I29/(1+H29*$B$5) -> 29.166667 | K29: 1.5 | L29: =G29/60*Machinery!$H$5*Assumptions!$B$23/100 -> 0.09 | M29: =G29/60*Machinery!$K$5 -> 0.2 | N29: =G29/60*Machinery!$L$5 -> 0.28571429 | O29: =F29/60*Assumptions!$B$20 -> 11.487923 | P29: =I29*Assumptions!$B$34*Assumptions!$B$35 -> 0.56525 | Q29: =SUM(K29:P29) -> 14.128887 | R29: =J29-Q29 -> 15.03778 | S29: =IF(J29=0,0,R29/J29) -> 0.51558102 | T29: =INDEX($B$13:$B$25,MATCH(E29,$A$13:$A$25,0)) -> 0.7 | U29: =SUM(K29:O29)/(1-T29-Assumptions!$B$34*Assumptions!$B$35*(1+H29*$B$5)) -> 48.334534 | V29: =MROUND(U29*(1+H29*$B$5),$B$6) -> 58 | W29: =IF(I29=0,0,V29/I29-1) -> 0.65714286 | X29: =MROUND(V29*3*(1-$B$7),$B$6) -> 157 | Y29: =MROUND(V29*6*(1-$B$8),$B$6) -> 296 | Z29: =MROUND(V29*10*(1-$B$9),$B$6) -> 464 | AC29: =IF(OR(D29="ACTIVE",D29="CONSULTATION"),1,0) -> 1
A30: Laser Hair Removal — Women | B30: Brazilian | C30: aesthetics | D30: CONSULTATION | E30: diode-laser | F30: 20 | G30: 20 | H30: 0.2 | I30: 43 | J30: =I30/(1+H30*$B$5) -> 35.833333 | K30: 1.5 | L30: =G30/60*Machinery!$H$5*Assumptions!$B$23/100 -> 0.09 | M30: =G30/60*Machinery!$K$5 -> 0.2 | N30: =G30/60*Machinery!$L$5 -> 0.28571429 | O30: =F30/60*Assumptions!$B$20 -> 11.487923 | P30: =I30*Assumptions!$B$34*Assumptions!$B$35 -> 0.69445 | Q30: =SUM(K30:P30) -> 14.258087 | R30: =J30-Q30 -> 21.575246 | S30: =IF(J30=0,0,R30/J30) -> 0.6020999 | T30: =INDEX($B$13:$B$25,MATCH(E30,$A$13:$A$25,0)) -> 0.7 | U30: =SUM(K30:O30)/(1-T30-Assumptions!$B$34*Assumptions!$B$35*(1+H30*$B$5)) -> 48.334534 | V30: =MROUND(U30*(1+H30*$B$5),$B$6) -> 58 | W30: =IF(I30=0,0,V30/I30-1) -> 0.34883721 | X30: =MROUND(V30*3*(1-$B$7),$B$6) -> 157 | Y30: =MROUND(V30*6*(1-$B$8),$B$6) -> 296 | Z30: =MROUND(V30*10*(1-$B$9),$B$6) -> 464 | AC30: =IF(OR(D30="ACTIVE",D30="CONSULTATION"),1,0) -> 1
A31: Laser Hair Removal — Women | B31: Hollywood Brazilian (incl. Peri-Anal) | C31: aesthetics | D31: CONSULTATION | E31: diode-laser | F31: 30 | G31: 30 | H31: 0.2 | I31: 54 | J31: =I31/(1+H31*$B$5) -> 45 | K31: 1.5 | L31: =G31/60*Machinery!$H$5*Assumptions!$B$23/100 -> 0.135 | M31: =G31/60*Machinery!$K$5 -> 0.3 | N31: =G31/60*Machinery!$L$5 -> 0.42857143 | O31: =F31/60*Assumptions!$B$20 -> 17.231884 | P31: =I31*Assumptions!$B$34*Assumptions!$B$35 -> 0.8721 | Q31: =SUM(K31:P31) -> 20.467555 | R31: =J31-Q31 -> 24.532445 | S31: =IF(J31=0,0,R31/J31) -> 0.54516543 | T31: =INDEX($B$13:$B$25,MATCH(E31,$A$13:$A$25,0)) -> 0.7 | U31: =SUM(K31:O31)/(1-T31-Assumptions!$B$34*Assumptions!$B$35*(1+H31*$B$5)) -> 69.829148 | V31: =MROUND(U31*(1+H31*$B$5),$B$6) -> 84 | W31: =IF(I31=0,0,V31/I31-1) -> 0.55555556 | X31: =MROUND(V31*3*(1-$B$7),$B$6) -> 227 | Y31: =MROUND(V31*6*(1-$B$8),$B$6) -> 428 | Z31: =MROUND(V31*10*(1-$B$9),$B$6) -> 672 | AC31: =IF(OR(D31="ACTIVE",D31="CONSULTATION"),1,0) -> 1
A32: Laser Hair Removal — Women | B32: Behind (Peri-Anal) | C32: aesthetics | D32: CONSULTATION | E32: diode-laser | F32: 20 | G32: 20 | H32: 0.2 | I32: 26 | J32: =I32/(1+H32*$B$5) -> 21.666667 | K32: 1.5 | L32: =G32/60*Machinery!$H$5*Assumptions!$B$23/100 -> 0.09 | M32: =G32/60*Machinery!$K$5 -> 0.2 | N32: =G32/60*Machinery!$L$5 -> 0.28571429 | O32: =F32/60*Assumptions!$B$20 -> 11.487923 | P32: =I32*Assumptions!$B$34*Assumptions!$B$35 -> 0.4199 | Q32: =SUM(K32:P32) -> 13.983537 | R32: =J32-Q32 -> 7.6831297 | S32: =IF(J32=0,0,R32/J32) -> 0.35460599 | T32: =INDEX($B$13:$B$25,MATCH(E32,$A$13:$A$25,0)) -> 0.7 | U32: =SUM(K32:O32)/(1-T32-Assumptions!$B$34*Assumptions!$B$35*(1+H32*$B$5)) -> 48.334534 | V32: =MROUND(U32*(1+H32*$B$5),$B$6) -> 58 | W32: =IF(I32=0,0,V32/I32-1) -> 1.2307692 | X32: =MROUND(V32*3*(1-$B$7),$B$6) -> 157 | Y32: =MROUND(V32*6*(1-$B$8),$B$6) -> 296 | Z32: =MROUND(V32*10*(1-$B$9),$B$6) -> 464 | AC32: =IF(OR(D32="ACTIVE",D32="CONSULTATION"),1,0) -> 1
A33: Laser Hair Removal — Women | B33: Brazilian/Bikini & Underarms | C33: aesthetics | D33: CONSULTATION | E33: diode-laser | F33: 30 | G33: 30 | H33: 0.2 | I33: 60 | J33: =I33/(1+H33*$B$5) -> 50 | K33: 1.5 | L33: =G33/60*Machinery!$H$5*Assumptions!$B$23/100 -> 0.135 | M33: =G33/60*Machinery!$K$5 -> 0.3 | N33: =G33/60*Machinery!$L$5 -> 0.42857143 | O33: =F33/60*Assumptions!$B$20 -> 17.231884 | P33: =I33*Assumptions!$B$34*Assumptions!$B$35 -> 0.969 | Q33: =SUM(K33:P33) -> 20.564455 | R33: =J33-Q33 -> 29.435545 | S33: =IF(J33=0,0,R33/J33) -> 0.58871089 | T33: =INDEX($B$13:$B$25,MATCH(E33,$A$13:$A$25,0)) -> 0.7 | U33: =SUM(K33:O33)/(1-T33-Assumptions!$B$34*Assumptions!$B$35*(1+H33*$B$5)) -> 69.829148 | V33: =MROUND(U33*(1+H33*$B$5),$B$6) -> 84 | W33: =IF(I33=0,0,V33/I33-1) -> 0.4 | X33: =MROUND(V33*3*(1-$B$7),$B$6) -> 227 | Y33: =MROUND(V33*6*(1-$B$8),$B$6) -> 428 | Z33: =MROUND(V33*10*(1-$B$9),$B$6) -> 672 | AC33: =IF(OR(D33="ACTIVE",D33="CONSULTATION"),1,0) -> 1
A34: Laser Hair Removal — Women | B34: Hollywood Brazilian (incl. Peri-Anal) & Underarms | C34: aesthetics | D34: CONSULTATION | E34: diode-laser | F34: 30 | G34: 30 | H34: 0.2 | I34: 64 | J34: =I34/(1+H34*$B$5) -> 53.333333 | K34: 1.5 | L34: =G34/60*Machinery!$H$5*Assumptions!$B$23/100 -> 0.135 | M34: =G34/60*Machinery!$K$5 -> 0.3 | N34: =G34/60*Machinery!$L$5 -> 0.42857143 | O34: =F34/60*Assumptions!$B$20 -> 17.231884 | P34: =I34*Assumptions!$B$34*Assumptions!$B$35 -> 1.0336 | Q34: =SUM(K34:P34) -> 20.629055 | R34: =J34-Q34 -> 32.704278 | S34: =IF(J34=0,0,R34/J34) -> 0.61320521 | T34: =INDEX($B$13:$B$25,MATCH(E34,$A$13:$A$25,0)) -> 0.7 | U34: =SUM(K34:O34)/(1-T34-Assumptions!$B$34*Assumptions!$B$35*(1+H34*$B$5)) -> 69.829148 | V34: =MROUND(U34*(1+H34*$B$5),$B$6) -> 84 | W34: =IF(I34=0,0,V34/I34-1) -> 0.3125 | X34: =MROUND(V34*3*(1-$B$7),$B$6) -> 227 | Y34: =MROUND(V34*6*(1-$B$8),$B$6) -> 428 | Z34: =MROUND(V34*10*(1-$B$9),$B$6) -> 672 | AC34: =IF(OR(D34="ACTIVE",D34="CONSULTATION"),1,0) -> 1
A35: Laser Hair Removal — Women | B35: Hollywood Brazilian (incl. Peri-Anal) & Full Legs | C35: aesthetics | D35: CONSULTATION | E35: diode-laser | F35: 40 | G35: 40 | H35: 0.2 | I35: 119 | J35: =I35/(1+H35*$B$5) -> 99.166667 | K35: 2 | L35: =G35/60*Machinery!$H$5*Assumptions!$B$23/100 -> 0.18 | M35: =G35/60*Machinery!$K$5 -> 0.4 | N35: =G35/60*Machinery!$L$5 -> 0.57142857 | O35: =F35/60*Assumptions!$B$20 -> 22.975845 | P35: =I35*Assumptions!$B$34*Assumptions!$B$35 -> 1.92185 | Q35: =SUM(K35:P35) -> 28.049124 | R35: =J35-Q35 -> 71.117543 | S35: =IF(J35=0,0,R35/J35) -> 0.71715169 | T35: =INDEX($B$13:$B$25,MATCH(E35,$A$13:$A$25,0)) -> 0.7 | U35: =SUM(K35:O35)/(1-T35-Assumptions!$B$34*Assumptions!$B$35*(1+H35*$B$5)) -> 93.105531 | V35: =MROUND(U35*(1+H35*$B$5),$B$6) -> 112 | W35: =IF(I35=0,0,V35/I35-1) -> -0.058823529 | X35: =MROUND(V35*3*(1-$B$7),$B$6) -> 302 | Y35: =MROUND(V35*6*(1-$B$8),$B$6) -> 571 | Z35: =MROUND(V35*10*(1-$B$9),$B$6) -> 896 | AC35: =IF(OR(D35="ACTIVE",D35="CONSULTATION"),1,0) -> 1
A36: Laser Hair Removal — Women | B36: Full Leg & Underarms | C36: aesthetics | D36: CONSULTATION | E36: diode-laser | F36: 30 | G36: 30 | H36: 0.2 | I36: 115 | J36: =I36/(1+H36*$B$5) -> 95.833333 | K36: 2 | L36: =G36/60*Machinery!$H$5*Assumptions!$B$23/100 -> 0.135 | M36: =G36/60*Machinery!$K$5 -> 0.3 | N36: =G36/60*Machinery!$L$5 -> 0.42857143 | O36: =F36/60*Assumptions!$B$20 -> 17.231884 | P36: =I36*Assumptions!$B$34*Assumptions!$B$35 -> 1.85725 | Q36: =SUM(K36:P36) -> 21.952705 | R36: =J36-Q36 -> 73.880628 | S36: =IF(J36=0,0,R36/J36) -> 0.77092829 | T36: =INDEX($B$13:$B$25,MATCH(E36,$A$13:$A$25,0)) -> 0.7 | U36: =SUM(K36:O36)/(1-T36-Assumptions!$B$34*Assumptions!$B$35*(1+H36*$B$5)) -> 71.610917 | V36: =MROUND(U36*(1+H36*$B$5),$B$6) -> 86 | W36: =IF(I36=0,0,V36/I36-1) -> -0.25217391 | X36: =MROUND(V36*3*(1-$B$7),$B$6) -> 232 | Y36: =MROUND(V36*6*(1-$B$8),$B$6) -> 439 | Z36: =MROUND(V36*10*(1-$B$9),$B$6) -> 688 | AC36: =IF(OR(D36="ACTIVE",D36="CONSULTATION"),1,0) -> 1
A37: Laser Hair Removal — Women | B37: Lower Leg, Brazilian/Bikini & Underarms | C37: aesthetics | D37: CONSULTATION | E37: diode-laser | F37: 40 | G37: 40 | H37: 0.2 | I37: 95 | J37: =I37/(1+H37*$B$5) -> 79.166667 | K37: 2 | L37: =G37/60*Machinery!$H$5*Assumptions!$B$23/100 -> 0.18 | M37: =G37/60*Machinery!$K$5 -> 0.4 | N37: =G37/60*Machinery!$L$5 -> 0.57142857 | O37: =F37/60*Assumptions!$B$20 -> 22.975845 | P37: =I37*Assumptions!$B$34*Assumptions!$B$35 -> 1.53425 | Q37: =SUM(K37:P37) -> 27.661524 | R37: =J37-Q37 -> 51.505143 | S37: =IF(J37=0,0,R37/J37) -> 0.65059128 | T37: =INDEX($B$13:$B$25,MATCH(E37,$A$13:$A$25,0)) -> 0.7 | U37: =SUM(K37:O37)/(1-T37-Assumptions!$B$34*Assumptions!$B$35*(1+H37*$B$5)) -> 93.105531 | V37: =MROUND(U37*(1+H37*$B$5),$B$6) -> 112 | W37: =IF(I37=0,0,V37/I37-1) -> 0.17894737 | X37: =MROUND(V37*3*(1-$B$7),$B$6) -> 302 | Y37: =MROUND(V37*6*(1-$B$8),$B$6) -> 571 | Z37: =MROUND(V37*10*(1-$B$9),$B$6) -> 896 | AC37: =IF(OR(D37="ACTIVE",D37="CONSULTATION"),1,0) -> 1
A38: Laser Hair Removal — Women | B38: Full Legs, Brazilian/Bikini & Underarms | C38: aesthetics | D38: CONSULTATION | E38: diode-laser | F38: 50 | G38: 50 | H38: 0.2 | I38: 121 | J38: =I38/(1+H38*$B$5) -> 100.83333 | K38: 2 | L38: =G38/60*Machinery!$H$5*Assumptions!$B$23/100 -> 0.225 | M38: =G38/60*Machinery!$K$5 -> 0.5 | N38: =G38/60*Machinery!$L$5 -> 0.71428571 | O38: =F38/60*Assumptions!$B$20 -> 28.719807 | P38: =I38*Assumptions!$B$34*Assumptions!$B$35 -> 1.95415 | Q38: =SUM(K38:P38) -> 34.113242 | R38: =J38-Q38 -> 66.720091 | S38: =IF(J38=0,0,R38/J38) -> 0.66168685 | T38: =INDEX($B$13:$B$25,MATCH(E38,$A$13:$A$25,0)) -> 0.7 | U38: =SUM(K38:O38)/(1-T38-Assumptions!$B$34*Assumptions!$B$35*(1+H38*$B$5)) -> 114.60014 | V38: =MROUND(U38*(1+H38*$B$5),$B$6) -> 138 | W38: =IF(I38=0,0,V38/I38-1) -> 0.14049587 | X38: =MROUND(V38*3*(1-$B$7),$B$6) -> 373 | Y38: =MROUND(V38*6*(1-$B$8),$B$6) -> 704 | Z38: =MROUND(V38*10*(1-$B$9),$B$6) -> 1104 | AC38: =IF(OR(D38="ACTIVE",D38="CONSULTATION"),1,0) -> 1
A39: Laser Hair Removal — Women | B39: Full Legs, Hollywood Brazilian (incl. Peri-Anal) & Underarms | C39: aesthetics | D39: CONSULTATION | E39: diode-laser | F39: 50 | G39: 50 | H39: 0.2 | I39: 149 | J39: =I39/(1+H39*$B$5) -> 124.16667 | K39: 2 | L39: =G39/60*Machinery!$H$5*Assumptions!$B$23/100 -> 0.225 | M39: =G39/60*Machinery!$K$5 -> 0.5 | N39: =G39/60*Machinery!$L$5 -> 0.71428571 | O39: =F39/60*Assumptions!$B$20 -> 28.719807 | P39: =I39*Assumptions!$B$34*Assumptions!$B$35 -> 2.40635 | Q39: =SUM(K39:P39) -> 34.565442 | R39: =J39-Q39 -> 89.601224 | S39: =IF(J39=0,0,R39/J39) -> 0.7216206 | T39: =INDEX($B$13:$B$25,MATCH(E39,$A$13:$A$25,0)) -> 0.7 | U39: =SUM(K39:O39)/(1-T39-Assumptions!$B$34*Assumptions!$B$35*(1+H39*$B$5)) -> 114.60014 | V39: =MROUND(U39*(1+H39*$B$5),$B$6) -> 138 | W39: =IF(I39=0,0,V39/I39-1) -> -0.073825503 | X39: =MROUND(V39*3*(1-$B$7),$B$6) -> 373 | Y39: =MROUND(V39*6*(1-$B$8),$B$6) -> 704 | Z39: =MROUND(V39*10*(1-$B$9),$B$6) -> 1104 | AC39: =IF(OR(D39="ACTIVE",D39="CONSULTATION"),1,0) -> 1
A40: Laser Hair Removal — Women | B40: Eyebrows (middle, above bridge of nose) | C40: aesthetics | D40: CONSULTATION | E40: diode-laser | F40: 15 | G40: 15 | H40: 0.2 | I40: 11 | J40: =I40/(1+H40*$B$5) -> 9.1666667 | K40: 1 | L40: =G40/60*Machinery!$H$5*Assumptions!$B$23/100 -> 0.0675 | M40: =G40/60*Machinery!$K$5 -> 0.15 | N40: =G40/60*Machinery!$L$5 -> 0.21428571 | O40: =F40/60*Assumptions!$B$20 -> 8.615942 | P40: =I40*Assumptions!$B$34*Assumptions!$B$35 -> 0.17765 | Q40: =SUM(K40:P40) -> 10.225378 | R40: =J40-Q40 -> -1.0587111 | S40: =IF(J40=0,0,R40/J40) -> -0.11549575 | T40: =INDEX($B$13:$B$25,MATCH(E40,$A$13:$A$25,0)) -> 0.7 | U40: =SUM(K40:O40)/(1-T40-Assumptions!$B$34*Assumptions!$B$35*(1+H40*$B$5)) -> 35.805458 | V40: =MROUND(U40*(1+H40*$B$5),$B$6) -> 43 | W40: =IF(I40=0,0,V40/I40-1) -> 2.9090909 | X40: =MROUND(V40*3*(1-$B$7),$B$6) -> 116 | Y40: =MROUND(V40*6*(1-$B$8),$B$6) -> 219 | Z40: =MROUND(V40*10*(1-$B$9),$B$6) -> 344 | AC40: =IF(OR(D40="ACTIVE",D40="CONSULTATION"),1,0) -> 1
... A88: Laser Hair Removal — Men | B88: Full Legs | C88: aesthetics | D88: ACTIVE | E88: diode-laser | F88: 60 | G88: 60 | H88: 0.2 | I88: 147 | J88: =I88/(1+H88*$B$5) -> 122.5 | K88: 2.5 | L88: =G88/60*Machinery!$H$5*Assumptions!$B$23/100 -> 0.27 | M88: =G88/60*Machinery!$K$5 -> 0.6 | N88: =G88/60*Machinery!$L$5 -> 0.85714286 | O88: =F88/60*Assumptions!$B$20 -> 34.463768 | P88: =I88*Assumptions!$B$34*Assumptions!$B$35 -> 2.37405 | Q88: =SUM(K88:P88) -> 41.064961 | R88: =J88-Q88 -> 81.435039 | S88: =IF(J88=0,0,R88/J88) -> 0.66477583 | T88: =INDEX($B$13:$B$25,MATCH(E88,$A$13:$A$25,0)) -> 0.7 | U88: =SUM(K88:O88)/(1-T88-Assumptions!$B$34*Assumptions!$B$35*(1+H88*$B$5)) -> 137.87653 | V88: =MROUND(U88*(1+H88*$B$5),$B$6) -> 165 | W88: =IF(I88=0,0,V88/I88-1) -> 0.12244898 | X88: =MROUND(V88*3*(1-$B$7),$B$6) -> 446 | Y88: =MROUND(V88*6*(1-$B$8),$B$6) -> 842 | Z88: =MROUND(V88*10*(1-$B$9),$B$6) -> 1320 | AC88: =IF(OR(D88="ACTIVE",D88="CONSULTATION"),1,0) -> 1
A89: Intimate Rejuvenation | B89: CO2 Laser Rejuvenation | C89: aesthetics | D89: COMING_SOON | E89: co2-laser | F89: 40 | G89: 40 | H89: 0.2 | I89: 690 | J89: =I89/(1+H89*$B$5) -> 575 | K89: 50 | L89: =G89/60*Machinery!$H$8*Assumptions!$B$23/100 -> 0.072 | M89: =G89/60*Machinery!$K$8 -> 27.777778 | N89: =G89/60*Machinery!$L$8 -> 42.438272 | O89: =F89/60*Assumptions!$B$20 -> 22.975845 | P89: =I89*Assumptions!$B$34*Assumptions!$B$35 -> 11.1435 | Q89: =SUM(K89:P89) -> 154.40739 | R89: =J89-Q89 -> 420.59261 | S89: =IF(J89=0,0,R89/J89) -> 0.7314654 | T89: =INDEX($B$13:$B$25,MATCH(E89,$A$13:$A$25,0)) -> 0.7 | U89: =SUM(K89:O89)/(1-T89-Assumptions!$B$34*Assumptions!$B$35*(1+H89*$B$5)) -> 510.52632 | V89: =MROUND(U89*(1+H89*$B$5),$B$6) -> 613 | W89: =IF(I89=0,0,V89/I89-1) -> -0.1115942 | X89: =MROUND(V89*3*(1-$B$7),$B$6) -> 1655 | Y89: =MROUND(V89*6*(1-$B$8),$B$6) -> 3126 | Z89: =MROUND(V89*10*(1-$B$9),$B$6) -> 4904 | AC89: =IF(OR(D89="ACTIVE",D89="CONSULTATION"),1,0) -> 0
A90: Intimate Rejuvenation | B90: Intimate Area Whitening | C90: aesthetics | D90: COMING_SOON | E90: co2-laser | F90: 40 | G90: 40 | H90: 0.2 | I90: 690 | J90: =I90/(1+H90*$B$5) -> 575 | K90: 50 | L90: =G90/60*Machinery!$H$8*Assumptions!$B$23/100 -> 0.072 | M90: =G90/60*Machinery!$K$8 -> 27.777778 | N90: =G90/60*Machinery!$L$8 -> 42.438272 | O90: =F90/60*Assumptions!$B$20 -> 22.975845 | P90: =I90*Assumptions!$B$34*Assumptions!$B$35 -> 11.1435 | Q90: =SUM(K90:P90) -> 154.40739 | R90: =J90-Q90 -> 420.59261 | S90: =IF(J90=0,0,R90/J90) -> 0.7314654 | T90: =INDEX($B$13:$B$25,MATCH(E90,$A$13:$A$25,0)) -> 0.7 | U90: =SUM(K90:O90)/(1-T90-Assumptions!$B$34*Assumptions!$B$35*(1+H90*$B$5)) -> 510.52632 | V90: =MROUND(U90*(1+H90*$B$5),$B$6) -> 613 | W90: =IF(I90=0,0,V90/I90-1) -> -0.1115942 | X90: =MROUND(V90*3*(1-$B$7),$B$6) -> 1655 | Y90: =MROUND(V90*6*(1-$B$8),$B$6) -> 3126 | Z90: =MROUND(V90*10*(1-$B$9),$B$6) -> 4904 | AC90: =IF(OR(D90="ACTIVE",D90="CONSULTATION"),1,0) -> 0
A91: Laser Pigmentation Removal | B91: Face | C91: aesthetics | D91: ACTIVE | E91: laser-ipl-platform | F91: 30 | G91: 30 | H91: 0.2 | I91: 150 | J91: =I91/(1+H91*$B$5) -> 125 | K91: 2 | L91: =G91/60*Machinery!$H$6*Assumptions!$B$23/100 -> 0.108 | M91: =G91/60*Machinery!$K$6 -> 4.1666667 | N91: =G91/60*Machinery!$L$6 -> 7.8125 | O91: =F91/60*Assumptions!$B$20 -> 17.231884 | P91: =I91*Assumptions!$B$34*Assumptions!$B$35 -> 2.4225 | Q91: =SUM(K91:P91) -> 33.741551 | R91: =J91-Q91 -> 91.258449 | S91: =IF(J91=0,0,R91/J91) -> 0.73006759 | T91: =INDEX($B$13:$B$25,MATCH(E91,$A$13:$A$25,0)) -> 0.7 | U91: =SUM(K91:O91)/(1-T91-Assumptions!$B$34*Assumptions!$B$35*(1+H91*$B$5)) -> 111.60662 | V91: =MROUND(U91*(1+H91*$B$5),$B$6) -> 134 | W91: =IF(I91=0,0,V91/I91-1) -> -0.10666667 | X91: =MROUND(V91*3*(1-$B$7),$B$6) -> 362 | Y91: =MROUND(V91*6*(1-$B$8),$B$6) -> 683 | Z91: =MROUND(V91*10*(1-$B$9),$B$6) -> 1072 | AC91: =IF(OR(D91="ACTIVE",D91="CONSULTATION"),1,0) -> 1
...

Sheet Volumes
A1: Volume & revenue forecast — capacity × utilisation × mix
A2: Room capacity comes from Assumptions. The utilisation ramp (blue row) is THE dominant free assumption — current run-rate is ~3% (225 bookings in the 90 days after the May 2026 reopening). Mix % splits treated hours across machine classes; seeded from live booking mix. Per-class average price/cost auto-computed from the Pricing tab (sellable variants); use the blue override column to demand-weight.
A4: Family | B4: Class key | C4: Avg session min (auto) | D4: Min override | E4: Min used | F4: Avg price £ (auto) | G4: Price override | H4: Price used £ | I4: Avg direct cost £ (auto) | J4: Cost override | K4: Cost used £ | L4: Machine min/session | M4: kWh/treatment hr | N4: Hours mix %
A5: Laser hair removal (diode) | B5: diode-laser | C5: =IFERROR(AVERAGEIFS(Pricing!$F$29:$F$194,Pricing!$E$29:$E$194,B5,Pricing!$AC$29:$AC$194,1),0) -> 30.25 | E5: =IF(D5<>"",D5,C5) -> 30.25 | F5: =IFERROR(AVERAGEIFS(Pricing!$I$29:$I$194,Pricing!$E$29:$E$194,B5,Pricing!$AC$29:$AC$194,1),0) -> 80.133333 | H5: =IF(G5<>"",G5,F5) -> 80.133333 | I5: =IFERROR(AVERAGEIFS(Pricing!$K$29:$K$194,Pricing!$E$29:$E$194,B5,Pricing!$AC$29:$AC$194,1)+AVERAGEIFS(Pricing!$L$29:$L$194,Pricing!$E$29:$E$194,B5,Pricing!$AC$29:$AC$194,1)+AVERAGEIFS(Pricing!$M$29:$M$194,Pricing!$E$29:$E$194,B5,Pricing!$AC$29:$AC$194,1),0) -> 2.113625 | K5: =IF(J5<>"",J5,I5) -> 2.113625 | L5: =IFERROR(AVERAGEIFS(Pricing!$G$29:$G$194,Pricing!$E$29:$E$194,B5,Pricing!$AC$29:$AC$194,1),0) -> 30.25 | M5: =Machinery!$H$5 -> 1 | N5: 0.495
A6: IPL / laser skin | B6: laser-ipl-platform | C6: =IFERROR(AVERAGEIFS(Pricing!$F$29:$F$194,Pricing!$E$29:$E$194,B6,Pricing!$AC$29:$AC$194,1),0) -> 35 | E6: =IF(D6<>"",D6,C6) -> 35 | F6: =IFERROR(AVERAGEIFS(Pricing!$I$29:$I$194,Pricing!$E$29:$E$194,B6,Pricing!$AC$29:$AC$194,1),0) -> 203.58333 | H6: =IF(G6<>"",G6,F6) -> 203.58333 | I6: =IFERROR(AVERAGEIFS(Pricing!$K$29:$K$194,Pricing!$E$29:$E$194,B6,Pricing!$AC$29:$AC$194,1)+AVERAGEIFS(Pricing!$L$29:$L$194,Pricing!$E$29:$E$194,B6,Pricing!$AC$29:$AC$194,1)+AVERAGEIFS(Pricing!$M$29:$M$194,Pricing!$E$29:$E$194,B6,Pricing!$AC$29:$AC$194,1),0) -> 7.0704444 | K6: =IF(J6<>"",J6,I6) -> 7.0704444 | L6: =IFERROR(AVERAGEIFS(Pricing!$G$29:$G$194,Pricing!$E$29:$E$194,B6,Pricing!$AC$29:$AC$194,1),0) -> 35 | M6: =Machinery!$H$6 -> 0.8 | N6: 0.03
A7: HIFU lifting | B7: hifu | C7: =IFERROR(AVERAGEIFS(Pricing!$F$29:$F$194,Pricing!$E$29:$E$194,B7,Pricing!$AC$29:$AC$194,1),0) -> 50 | E7: =IF(D7<>"",D7,C7) -> 50 | F7: =IFERROR(AVERAGEIFS(Pricing!$I$29:$I$194,Pricing!$E$29:$E$194,B7,Pricing!$AC$29:$AC$194,1),0) -> 376.69231 | H7: =IF(G7<>"",G7,F7) -> 376.69231 | I7: =IFERROR(AVERAGEIFS(Pricing!$K$29:$K$194,Pricing!$E$29:$E$194,B7,Pricing!$AC$29:$AC$194,1)+AVERAGEIFS(Pricing!$L$29:$L$194,Pricing!$E$29:$E$194,B7,Pricing!$AC$29:$AC$194,1)+AVERAGEIFS(Pricing!$M$29:$M$194,Pricing!$E$29:$E$194,B7,Pricing!$AC$29:$AC$194,1),0) -> 70.548269 | K7: =IF(J7<>"",J7,I7) -> 70.548269 | L7: =IFERROR(AVERAGEIFS(Pricing!$G$29:$G$194,Pricing!$E$29:$E$194,B7,Pricing!$AC$29:$AC$194,1),0) -> 50 | M7: =Machinery!$H$9 -> 0.3 | N7: 0.02
A8: RF tightening | B8: rf-tightening | C8: =IFERROR(AVERAGEIFS(Pricing!$F$29:$F$194,Pricing!$E$29:$E$194,B8,Pricing!$AC$29:$AC$194,1),0) -> 60 | E8: =IF(D8<>"",D8,C8) -> 60 | F8: =IFERROR(AVERAGEIFS(Pricing!$I$29:$I$194,Pricing!$E$29:$E$194,B8,Pricing!$AC$29:$AC$194,1),0) -> 260 | H8: =IF(G8<>"",G8,F8) -> 260 | I8: =IFERROR(AVERAGEIFS(Pricing!$K$29:$K$194,Pricing!$E$29:$E$194,B8,Pricing!$AC$29:$AC$194,1)+AVERAGEIFS(Pricing!$L$29:$L$194,Pricing!$E$29:$E$194,B8,Pricing!$AC$29:$AC$194,1)+AVERAGEIFS(Pricing!$M$29:$M$194,Pricing!$E$29:$E$194,B8,Pricing!$AC$29:$AC$194,1),0) -> 23.968333 | K8: =IF(J8<>"",J8,I8) -> 23.968333 | L8: =IFERROR(AVERAGEIFS(Pricing!$G$29:$G$194,Pricing!$E$29:$E$194,B8,Pricing!$AC$29:$AC$194,1),0) -> 60 | M8: =Machinery!$H$10 -> 0.5 | N8: 0.02
A9: HydraFacial & facials | B9: hydrafacial-platform | C9: =IFERROR(AVERAGEIFS(Pricing!$F$29:$F$194,Pricing!$E$29:$E$194,B9,Pricing!$AC$29:$AC$194,1),0) -> 65.909091 | E9: =IF(D9<>"",D9,C9) -> 65.909091 | F9: =IFERROR(AVERAGEIFS(Pricing!$I$29:$I$194,Pricing!$E$29:$E$194,B9,Pricing!$AC$29:$AC$194,1),0) -> 157.72727 | H9: =IF(G9<>"",G9,F9) -> 157.72727 | I9: =IFERROR(AVERAGEIFS(Pricing!$K$29:$K$194,Pricing!$E$29:$E$194,B9,Pricing!$AC$29:$AC$194,1)+AVERAGEIFS(Pricing!$L$29:$L$194,Pricing!$E$29:$E$194,B9,Pricing!$AC$29:$AC$194,1)+AVERAGEIFS(Pricing!$M$29:$M$194,Pricing!$E$29:$E$194,B9,Pricing!$AC$29:$AC$194,1),0) -> 20.984192 | K9: =IF(J9<>"",J9,I9) -> 20.984192 | L9: =IFERROR(AVERAGEIFS(Pricing!$G$29:$G$194,Pricing!$E$29:$E$194,B9,Pricing!$AC$29:$AC$194,1),0) -> 65.909091 | M9: =Machinery!$H$11 -> 0.2 | N9: 0.11
A10: Body contouring (Endosphere/vacuum) | B10: endosphere-vacuum | C10: =IFERROR(AVERAGEIFS(Pricing!$F$29:$F$194,Pricing!$E$29:$E$194,B10,Pricing!$AC$29:$AC$194,1),0) -> 51.428571 | E10: =IF(D10<>"",D10,C10) -> 51.428571 | F10: =IFERROR(AVERAGEIFS(Pricing!$I$29:$I$194,Pricing!$E$29:$E$194,B10,Pricing!$AC$29:$AC$194,1),0) -> 103.57143 | H10: =IF(G10<>"",G10,F10) -> 103.57143 | I10: =IFERROR(AVERAGEIFS(Pricing!$K$29:$K$194,Pricing!$E$29:$E$194,B10,Pricing!$AC$29:$AC$194,1)+AVERAGEIFS(Pricing!$L$29:$L$194,Pricing!$E$29:$E$194,B10,Pricing!$AC$29:$AC$194,1)+AVERAGEIFS(Pricing!$M$29:$M$194,Pricing!$E$29:$E$194,B10,Pricing!$AC$29:$AC$194,1),0) -> 4.9302063 | K10: =IF(J10<>"",J10,I10) -> 4.9302063 | L10: =IFERROR(AVERAGEIFS(Pricing!$G$29:$G$194,Pricing!$E$29:$E$194,B10,Pricing!$AC$29:$AC$194,1),0) -> 51.428571 | M10: =Machinery!$H$12 -> 0.35 | N10: 0.08
A11: Microneedling & BB Glow | B11: microneedling-pen | C11: =IFERROR(AVERAGEIFS(Pricing!$F$29:$F$194,Pricing!$E$29:$E$194,B11,Pricing!$AC$29:$AC$194,1),0) -> 60 | E11: =IF(D11<>"",D11,C11) -> 60 | F11: =IFERROR(AVERAGEIFS(Pricing!$I$29:$I$194,Pricing!$E$29:$E$194,B11,Pricing!$AC$29:$AC$194,1),0) -> 125 | H11: =IF(G11<>"",G11,F11) -> 125 | I11: =IFERROR(AVERAGEIFS(Pricing!$K$29:$K$194,Pricing!$E$29:$E$194,B11,Pricing!$AC$29:$AC$194,1)+AVERAGEIFS(Pricing!$L$29:$L$194,Pricing!$E$29:$E$194,B11,Pricing!$AC$29:$AC$194,1)+AVERAGEIFS(Pricing!$M$29:$M$194,Pricing!$E$29:$E$194,B11,Pricing!$AC$29:$AC$194,1),0) -> 25.968363 | K11: =IF(J11<>"",J11,I11) -> 25.968363 | L11: =IFERROR(AVERAGEIFS(Pricing!$G$29:$G$194,Pricing!$E$29:$E$194,B11,Pricing!$AC$29:$AC$194,1),0) -> 60 | M11: =Machinery!$H$13 -> 0.02 | N11: 0.03
A12: Microdermabrasion | B12: microdermabrasion | C12: =IFERROR(AVERAGEIFS(Pricing!$F$29:$F$194,Pricing!$E$29:$E$194,B12,Pricing!$AC$29:$AC$194,1),0) -> 30 | E12: =IF(D12<>"",D12,C12) -> 30 | F12: =IFERROR(AVERAGEIFS(Pricing!$I$29:$I$194,Pricing!$E$29:$E$194,B12,Pricing!$AC$29:$AC$194,1),0) -> 80 | H12: =IF(G12<>"",G12,F12) -> 80 | I12: =IFERROR(AVERAGEIFS(Pricing!$K$29:$K$194,Pricing!$E$29:$E$194,B12,Pricing!$AC$29:$AC$194,1)+AVERAGEIFS(Pricing!$L$29:$L$194,Pricing!$E$29:$E$194,B12,Pricing!$AC$29:$AC$194,1)+AVERAGEIFS(Pricing!$M$29:$M$194,Pricing!$E$29:$E$194,B12,Pricing!$AC$29:$AC$194,1),0) -> 3.59625 | K12: =IF(J12<>"",J12,I12) -> 3.59625 | L12: =IFERROR(AVERAGEIFS(Pricing!$G$29:$G$194,Pricing!$E$29:$E$194,B12,Pricing!$AC$29:$AC$194,1),0) -> 30 | M12: =Machinery!$H$14 -> 0.25 | N12: 0.005
